Workbook

Sheet Calculos
A1: 1. Ingreso de cuencas y parámetros morfológicos.
A2: Parametro | B2: Unidad
A3: Cuenca
A4: Area | B4: (km2)
A5: Curva Numero | B5: (-)
A6: Elevacion Minima | B6: (m s.n.m.)
A7: Elevacion Maxima | B7: (m s.n.m.)
A8: Rango Elevacion | B8: (m)
A9: Elevacion Media | B9: (m s.n.m.)
A10: Pendiente Media Cauce Principal | B10: (m/m)
A11: Largo Cauce Principal | B11: (km)
A12: Largo Cauce - Centro de Gravedad | B12: (km)
A13: Velocidad Media Cauce Principal | B13: (m/s)
A16: 2. Cálculo tiempos de concentración y adopción de tiempo de concentración para cada cuenca
A17: Tiempos de concentración | B17: Unidad
A18: California Culverts Practice | B18: (hr) | C18: =IF(OR(C11="",C8=""),"",IF(OR(C11<=0,C8<=0),"",0.95*((C11^3)/C8)^0.385)) | D18: =IF(OR(D11="",D8=""),"",IF(OR(D11<=0,D8<=0),"",0.95*((D11^3)/D8)^0.385)) | E18: =IF(OR(E11="",E8=""),"",IF(OR(E11<=0,E8<=0),"",0.95*((E11^3)/E8)^0.385)) | F18: =IF(OR(F11="",F8=""),"",IF(OR(F11<=0,F8<=0),"",0.95*((F11^3)/F8)^0.385)) | G18: =IF(OR(G11="",G8=""),"",IF(OR(G11<=0,G8<=0),"",0.95*((G11^3)/G8)^0.385)) | H18: =IF(OR(H11="",H8=""),"",IF(OR(H11<=0,H8<=0),"",0.95*((H11^3)/H8)^0.385)) | I18: =IF(OR(I11="",I8=""),"",IF(OR(I11<=0,I8<=0),"",0.95*((I11^3)/I8)^0.385)) | J18: =IF(OR(J11="",J8=""),"",IF(OR(J11<=0,J8<=0),"",0.95*((J11^3)/J8)^0.385)) | ... O18: =IF(OR(O11="",O8=""),"",IF(OR(O11<=0,O8<=0),"",0.95*((O11^3)/O8)^0.385))
A19: Giandotti | B19: (hr) | C19: =IF(OR(C4="",C11="",C9="",C6=""),"",IF(OR(C4<=0,C11<=0,C9<=C6),"",(4*SQRT(C4)+1.5*C11)/(0.8*SQRT(C9-C6)))) | D19: =IF(OR(D4="",D11="",D9="",D6=""),"",IF(OR(D4<=0,D11<=0,D9<=D6),"",(4*SQRT(D4)+1.5*D11)/(0.8*SQRT(D9-D6)))) | E19: =IF(OR(E4="",E11="",E9="",E6=""),"",IF(OR(E4<=0,E11<=0,E9<=E6),"",(4*SQRT(E4)+1.5*E11)/(0.8*SQRT(E9-E6)))) | F19: =IF(OR(F4="",F11="",F9="",F6=""),"",IF(OR(F4<=0,F11<=0,F9<=F6),"",(4*SQRT(F4)+1.5*F11)/(0.8*SQRT(F9-F6)))) | G19: =IF(OR(G4="",G11="",G9="",G6=""),"",IF(OR(G4<=0,G11<=0,G9<=G6),"",(4*SQRT(G4)+1.5*G11)/(0.8*SQRT(G9-G6)))) | H19: =IF(OR(H4="",H11="",H9="",H6=""),"",IF(OR(H4<=0,H11<=0,H9<=H6),"",(4*SQRT(H4)+1.5*H11)/(0.8*SQRT(H9-H6)))) | I19: =IF(OR(I4="",I11="",I9="",I6=""),"",IF(OR(I4<=0,I11<=0,I9<=I6),"",(4*SQRT(I4)+1.5*I11)/(0.8*SQRT(I9-I6)))) | J19: =IF(OR(J4="",J11="",J9="",J6=""),"",IF(OR(J4<=0,J11<=0,J9<=J6),"",(4*SQRT(J4)+1.5*J11)/(0.8*SQRT(J9-J6)))) | ... O19: =IF(OR(O4="",O11="",O9="",O6=""),"",IF(OR(O4<=0,O11<=0,O9<=O6),"",(4*SQRT(O4)+1.5*O11)/(0.8*SQRT(O9-O6))))
A20: SCS | B20: (hr) | C20: =IF(OR(C11="",C5="",C10=""),"",IF(OR(C11<=0,C10<=0,C5<=0,C5>100),"",((100*((C11*1000/0.3048)^0.8)*(((1000/C5)-9)^0.7))/(1900*SQRT(C10*100)))/60)) | D20: =IF(OR(D11="",D5="",D10=""),"",IF(OR(D11<=0,D10<=0,D5<=0,D5>100),"",((100*((D11*1000/0.3048)^0.8)*(((1000/D5)-9)^0.7))/(1900*SQRT(D10*100)))/60)) | E20: =IF(OR(E11="",E5="",E10=""),"",IF(OR(E11<=0,E10<=0,E5<=0,E5>100),"",((100*((E11*1000/0.3048)^0.8)*(((1000/E5)-9)^0.7))/(1900*SQRT(E10*100)))/60)) | F20: =IF(OR(F11="",F5="",F10=""),"",IF(OR(F11<=0,F10<=0,F5<=0,F5>100),"",((100*((F11*1000/0.3048)^0.8)*(((1000/F5)-9)^0.7))/(1900*SQRT(F10*100)))/60)) | G20: =IF(OR(G11="",G5="",G10=""),"",IF(OR(G11<=0,G10<=0,G5<=0,G5>100),"",((100*((G11*1000/0.3048)^0.8)*(((1000/G5)-9)^0.7))/(1900*SQRT(G10*100)))/60)) | H20: =IF(OR(H11="",H5="",H10=""),"",IF(OR(H11<=0,H10<=0,H5<=0,H5>100),"",((100*((H11*1000/0.3048)^0.8)*(((1000/H5)-9)^0.7))/(1900*SQRT(H10*100)))/60)) | I20: =IF(OR(I11="",I5="",I10=""),"",IF(OR(I11<=0,I10<=0,I5<=0,I5>100),"",((100*((I11*1000/0.3048)^0.8)*(((1000/I5)-9)^0.7))/(1900*SQRT(I10*100)))/60)) | J20: =IF(OR(J11="",J5="",J10=""),"",IF(OR(J11<=0,J10<=0,J5<=0,J5>100),"",((100*((J11*1000/0.3048)^0.8)*(((1000/J5)-9)^0.7))/(1900*SQRT(J10*100)))/60)) | ... O20: =IF(OR(O11="",O5="",O10=""),"",IF(OR(O11<=0,O10<=0,O5<=0,O5>100),"",((100*((O11*1000/0.3048)^0.8)*(((1000/O5)-9)^0.7))/(1900*SQRT(O10*100)))/60))
A21: Normas Españolas | B21: (hr) | C21: =IF(OR(C11="",C10=""),"",IF(OR(C11<=0,C10<=0),"",(18*(C11^0.76)/(C10^0.19))/60)) | D21: =IF(OR(D11="",D10=""),"",IF(OR(D11<=0,D10<=0),"",(18*(D11^0.76)/(D10^0.19))/60)) | E21: =IF(OR(E11="",E10=""),"",IF(OR(E11<=0,E10<=0),"",(18*(E11^0.76)/(E10^0.19))/60)) | F21: =IF(OR(F11="",F10=""),"",IF(OR(F11<=0,F10<=0),"",(18*(F11^0.76)/(F10^0.19))/60)) | G21: =IF(OR(G11="",G10=""),"",IF(OR(G11<=0,G10<=0),"",(18*(G11^0.76)/(G10^0.19))/60)) | H21: =IF(OR(H11="",H10=""),"",IF(OR(H11<=0,H10<=0),"",(18*(H11^0.76)/(H10^0.19))/60)) | I21: =IF(OR(I11="",I10=""),"",IF(OR(I11<=0,I10<=0),"",(18*(I11^0.76)/(I10^0.19))/60)) | J21: =IF(OR(J11="",J10=""),"",IF(OR(J11<=0,J10<=0),"",(18*(J11^0.76)/(J10^0.19))/60)) | ... O21: =IF(OR(O11="",O10=""),"",IF(OR(O11<=0,O10<=0),"",(18*(O11^0.76)/(O10^0.19))/60))
A22: Velocidad Media | B22: (hr) | C22: =IF(OR(C11="",C13=""),"",IF(OR(C11<=0,C13<=0),"",C11/(3.6*C13))) | D22: =IF(OR(D11="",D13=""),"",IF(OR(D11<=0,D13<=0),"",D11/(3.6*D13))) | E22: =IF(OR(E11="",E13=""),"",IF(OR(E11<=0,E13<=0),"",E11/(3.6*E13))) | F22: =IF(OR(F11="",F13=""),"",IF(OR(F11<=0,F13<=0),"",F11/(3.6*F13))) | G22: =IF(OR(G11="",G13=""),"",IF(OR(G11<=0,G13<=0),"",G11/(3.6*G13))) | H22: =IF(OR(H11="",H13=""),"",IF(OR(H11<=0,H13<=0),"",H11/(3.6*H13))) | I22: =IF(OR(I11="",I13=""),"",IF(OR(I11<=0,I13<=0),"",I11/(3.6*I13))) | J22: =IF(OR(J11="",J13=""),"",IF(OR(J11<=0,J13<=0),"",J11/(3.6*J13))) | ... O22: =IF(OR(O11="",O13=""),"",IF(OR(O11<=0,O13<=0),"",O11/(3.6*O13)))
A23: Tiempo de Concentración Adoptado | B23: (hr)
D24: =IF(OR(D20="",D17=""),"",IF(OR(D20<=0,D17<=0),"",0.95*((D20^3)/D17)^0.385)) | E24: =IF(OR(E20="",E17=""),"",IF(OR(E20<=0,E17<=0),"",0.95*((E20^3)/E17)^0.385)) | F24: =IF(OR(F20="",F17=""),"",IF(OR(F20<=0,F17<=0),"",0.95*((F20^3)/F17)^0.385)) | G24: =IF(OR(G20="",G17=""),"",IF(OR(G20<=0,G17<=0),"",0.95*((G20^3)/G17)^0.385)) | H24: =IF(OR(H20="",H17=""),"",IF(OR(H20<=0,H17<=0),"",0.95*((H20^3)/H17)^0.385)) | I24: =IF(OR(I20="",I17=""),"",IF(OR(I20<=0,I17<=0),"",0.95*((I20^3)/I17)^0.385)) | J24: =IF(OR(J20="",J17=""),"",IF(OR(J20<=0,J17<=0),"",0.95*((J20^3)/J17)^0.385)) | K24: =IF(OR(K20="",K17=""),"",IF(OR(K20<=0,K17<=0),"",0.95*((K20^3)/K17)^0.385)) | ... O24: =IF(OR(O20="",O17=""),"",IF(OR(O20<=0,O17<=0),"",0.95*((O20^3)/O17)^0.385))
A29: 3. Ingreso de coeficientes y cálculo C(T=10) y CD Bell
A30: Parametro | B30: Unidad
A31: Cuenca | C31: =IF(ISBLANK(Calculos!C3),"",Calculos!C3) | D31: =IF(ISBLANK(Calculos!D3),"",Calculos!D3) | E31: =IF(ISBLANK(Calculos!E3),"",Calculos!E3) | F31: =IF(ISBLANK(Calculos!F3),"",Calculos!F3) | G31: =IF(ISBLANK(Calculos!G3),"",Calculos!G3) | H31: =IF(ISBLANK(Calculos!H3),"",Calculos!H3) | I31: =IF(ISBLANK(Calculos!I3),"",Calculos!I3) | J31: =IF(ISBLANK(Calculos!J3),"",Calculos!J3) | ... O31: =IF(ISBLANK(Calculos!O3),"",Calculos!O3)
A32: CD1hr | B32: (-)
A33: Relieve | B33: (-)
A34: Infiltracion | B34: (-)
A35: Vegetacion | B35: (-)
A36: Almacenamiento Superficial | B36: (-)
A37: C(T=10) | B37: (-) | C37: =IF(OR(ISBLANK(C33),ISBLANK(C34),ISBLANK(C35),ISBLANK(C36)),"",SUM(C33:C36)) | D37: =IF(OR(ISBLANK(D33),ISBLANK(D34),ISBLANK(D35),ISBLANK(D36)),"",SUM(D33:D36)) | E37: =IF(OR(ISBLANK(E33),ISBLANK(E34),ISBLANK(E35),ISBLANK(E36)),"",SUM(E33:E36)) | F37: =IF(OR(ISBLANK(F33),ISBLANK(F34),ISBLANK(F35),ISBLANK(F36)),"",SUM(F33:F36)) | G37: =IF(OR(ISBLANK(G33),ISBLANK(G34),ISBLANK(G35),ISBLANK(G36)),"",SUM(G33:G36)) | H37: =IF(OR(ISBLANK(H33),ISBLANK(H34),ISBLANK(H35),ISBLANK(H36)),"",SUM(H33:H36)) | I37: =IF(OR(ISBLANK(I33),ISBLANK(I34),ISBLANK(I35),ISBLANK(I36)),"",SUM(I33:I36)) | J37: =IF(OR(ISBLANK(J33),ISBLANK(J34),ISBLANK(J35),ISBLANK(J36)),"",SUM(J33:J36)) | ... O37: =IF(OR(ISBLANK(O33),ISBLANK(O34),ISBLANK(O35),ISBLANK(O36)),"",SUM(O33:O36))
A38: CD Bell | B38: (-) | C38: =IF((C23<=0),"",0.54*(C23*60)^0.25-0.5) | D38: =IF((D23<=0),"",0.54*(D23*60)^0.25-0.5) | E38: =IF((E23<=0),"",0.54*(E23*60)^0.25-0.5) | F38: =IF((F23<=0),"",0.54*(F23*60)^0.25-0.5) | G38: =IF((G23<=0),"",0.54*(G23*60)^0.25-0.5) | H38: =IF((H23<=0),"",0.54*(H23*60)^0.25-0.5) | I38: =IF((I23<=0),"",0.54*(I23*60)^0.25-0.5) | J38: =IF((J23<=0),"",0.54*(J23*60)^0.25-0.5) | ... O38: =IF((O23<=0),"",0.54*(O23*60)^0.25-0.5)
A40: 4. Ingreso de periodos de retorno y precipitaciones máximas en 24 horas, PT24 (mm)
B41: Precipitaciones Máximas en 24 horas, PT24 (mm)
B42: T (años) | C42: =IF(ISBLANK(C3),"",C3) | D42: =IF(ISBLANK(D3),"",D3) | E42: =IF(ISBLANK(E3),"",E3) | F42: =IF(ISBLANK(F3),"",F3) | G42: =IF(ISBLANK(G3),"",G3) | H42: =IF(ISBLANK(H3),"",H3) | I42: =IF(ISBLANK(I3),"",I3) | J42: =IF(ISBLANK(J3),"",J3) | ... O42: =IF(ISBLANK(O3),"",O3)
A54: 5. Ingreso valores coeficientes de ajuste para C según período de retorno
B55: Coeficientes Ajuste C para distintos T
B56: T (años) | C56: Coeficiente
B57: =IF(ISBLANK(B43),"",B43)
B58: =IF(ISBLANK(B44),"",B44)
...
